[debug] [2025-08-20T23:09:53.250Z] ----------------------------------------------------------------------
[debug] [2025-08-20T23:09:53.251Z] Command:       /Users/andy/.nvm/versions/node/v20.19.0/bin/node /Users/andy/.nvm/versions/node/v20.19.0/bin/firebase login
[debug] [2025-08-20T23:09:53.251Z] CLI Version:   14.12.0
[debug] [2025-08-20T23:09:53.251Z] Platform:      darwin
[debug] [2025-08-20T23:09:53.251Z] Node Version:  v20.19.0
[debug] [2025-08-20T23:09:53.251Z] Time:          Thu Aug 21 2025 07:09:53 GMT+0800 (中国标准时间)
[debug] [2025-08-20T23:09:53.251Z] ----------------------------------------------------------------------
[debug] 
[debug] [2025-08-20T23:09:53.252Z] >>> [apiv2][query] GET https://firebase-public.firebaseio.com/cli.json [none]
[info] Already logged in as ldliangcool@gmail.com
[debug] [2025-08-20T23:10:03.277Z] Error: Timed out.
    at Timeout._onTimeout (/Users/andy/.nvm/versions/node/v20.19.0/lib/node_modules/firebase-tools/lib/utils.js:272:49)
    at listOnTimeout (node:internal/timers:581:17)
    at process.processTimers (node:internal/timers:519:7)
[error] 
[error] Error: An unexpected error has occurred.
[debug] [2025-08-20T23:10:32.301Z] ----------------------------------------------------------------------
[debug] [2025-08-20T23:10:32.302Z] Command:       /Users/andy/.nvm/versions/node/v20.19.0/bin/node /Users/andy/.nvm/versions/node/v20.19.0/bin/firebase login --reauth
[debug] [2025-08-20T23:10:32.303Z] CLI Version:   14.12.0
[debug] [2025-08-20T23:10:32.303Z] Platform:      darwin
[debug] [2025-08-20T23:10:32.303Z] Node Version:  v20.19.0
[debug] [2025-08-20T23:10:32.303Z] Time:          Thu Aug 21 2025 07:10:32 GMT+0800 (中国标准时间)
[debug] [2025-08-20T23:10:32.303Z] ----------------------------------------------------------------------
[debug] 
[debug] [2025-08-20T23:10:32.304Z] >>> [apiv2][query] GET https://firebase-public.firebaseio.com/cli.json [none]
[info] 
[info] Visit this URL on this device to log in:
[info] https://accounts.google.com/o/oauth2/auth?client_id=563584335869-fgrhgmd47bqnekij5i8b5pr03ho849e6.apps.googleusercontent.com&scope=email%20openid%20https%3A%2F%2Fwww.googleapis.com%2Fauth%2Fcloudplatformprojects.readonly%20https%3A%2F%2Fwww.googleapis.com%2Fauth%2Ffirebase%20https%3A%2F%2Fwww.googleapis.com%2Fauth%2Fcloud-platform&response_type=code&state=401485548&redirect_uri=http%3A%2F%2Flocalhost%3A9005&login_hint=ldliangcool%40gmail.com
[info] 
[info] Waiting for authentication...
[debug] [2025-08-20T23:10:37.657Z] >>> [apiv2][query] POST https://accounts.google.com/o/oauth2/token [none]
[debug] [2025-08-20T23:10:37.658Z] >>> [apiv2][body] POST https://accounts.google.com/o/oauth2/token [omitted]
[debug] [2025-08-20T23:11:02.323Z] *** [apiv2] error from fetch(https://firebase-public.firebaseio.com/cli.json, {"headers":{},"method":"GET"}): FetchError: request to https://firebase-public.firebaseio.com/cli.json failed, reason: getaddrinfo ENOTFOUND firebase-public.firebaseio.com
[warn] ⚠  Unable to fetch the CLI MOTD and remote config. This is not a fatal error, but may indicate an issue with your network connection. 
[debug] [2025-08-20T23:11:02.323Z] Failed to fetch MOTD FirebaseError: Failed to make request to https://firebase-public.firebaseio.com/cli.json
[debug] [2025-08-20T23:11:07.660Z] *** [apiv2] error from fetch(https://accounts.google.com/o/oauth2/token, {"headers":{},"method":"POST","body":{"_overheadLength":543,"_valueLength":208,"_valuesToMeasure":[],"writable":false,"readable":true,"dataSize":0,"maxDataSize":2097152,"pauseStreams":true,"_released":true,"_streams":[],"_currentStream":null,"_insideLoop":false,"_pendingNext":false,"_boundary":"--------------------------c2a615b5e1a95cb27256f19e","_events":{},"_eventsCount":1}}): FetchError: request to https://accounts.google.com/o/oauth2/token failed, reason: getaddrinfo ENOTFOUND accounts.google.com
[debug] [2025-08-20T23:11:07.660Z] Token Fetch Error: FirebaseError: Failed to make request to https://accounts.google.com/o/oauth2/token
    at RetryOperation._fn (/Users/andy/.nvm/versions/node/v20.19.0/lib/node_modules/firebase-tools/lib/apiv2.js:261:31)
    at process.processTicksAndRejections (node:internal/process/task_queues:95:5)
[error] Authentication Error: Your credentials are no longer valid. Please run firebase login --reauth

For CI servers and headless environments, generate a new token with firebase login:ci
[debug] [2025-08-20T23:11:07.662Z] >>> [apiv2][query] POST https://auth.firebase.tools/attest [none]
[debug] [2025-08-20T23:11:07.662Z] >>> [apiv2][body] POST https://auth.firebase.tools/attest {"session_id":"a36a2ddf-1e67-459c-9a89-45781fbe4226"}
[debug] [2025-08-20T23:11:37.664Z] *** [apiv2] error from fetch(https://auth.firebase.tools/attest, {"headers":{},"method":"POST","body":"{\"session_id\":\"a36a2ddf-1e67-459c-9a89-45781fbe4226\"}"}): FetchError: request to https://auth.firebase.tools/attest failed, reason: getaddrinfo ENOTFOUND auth.firebase.tools
[debug] [2025-08-20T23:11:42.667Z] Error: Timed out.
    at Timeout._onTimeout (/Users/andy/.nvm/versions/node/v20.19.0/lib/node_modules/firebase-tools/lib/utils.js:272:49)
    at listOnTimeout (node:internal/timers:581:17)
    at process.processTimers (node:internal/timers:519:7)
[error] 
[error] Error: An unexpected error has occurred.
[debug] [2025-08-20T23:16:49.572Z] ----------------------------------------------------------------------
[debug] [2025-08-20T23:16:49.573Z] Command:       /Users/andy/.nvm/versions/node/v20.19.0/bin/node /Users/andy/.nvm/versions/node/v20.19.0/bin/firebase login --reauth
[debug] [2025-08-20T23:16:49.573Z] CLI Version:   14.12.0
[debug] [2025-08-20T23:16:49.573Z] Platform:      darwin
[debug] [2025-08-20T23:16:49.573Z] Node Version:  v20.19.0
[debug] [2025-08-20T23:16:49.573Z] Time:          Thu Aug 21 2025 07:16:49 GMT+0800 (中国标准时间)
[debug] [2025-08-20T23:16:49.573Z] ----------------------------------------------------------------------
[debug] 
[debug] [2025-08-20T23:16:49.574Z] >>> [apiv2][query] GET https://firebase-public.firebaseio.com/cli.json [none]
[info] 
[info] Visit this URL on this device to log in:
[info] https://accounts.google.com/o/oauth2/auth?client_id=563584335869-fgrhgmd47bqnekij5i8b5pr03ho849e6.apps.googleusercontent.com&scope=email%20openid%20https%3A%2F%2Fwww.googleapis.com%2Fauth%2Fcloudplatformprojects.readonly%20https%3A%2F%2Fwww.googleapis.com%2Fauth%2Ffirebase%20https%3A%2F%2Fwww.googleapis.com%2Fauth%2Fcloud-platform&response_type=code&state=530385278&redirect_uri=http%3A%2F%2Flocalhost%3A9005&login_hint=ldliangcool%40gmail.com
[info] 
[info] Waiting for authentication...
[debug] [2025-08-20T23:16:52.719Z] >>> [apiv2][query] POST https://accounts.google.com/o/oauth2/token [none]
[debug] [2025-08-20T23:16:52.719Z] >>> [apiv2][body] POST https://accounts.google.com/o/oauth2/token [omitted]
[debug] [2025-08-20T23:16:56.287Z] <<< [apiv2][status] POST https://accounts.google.com/o/oauth2/token 200
[debug] [2025-08-20T23:16:56.288Z] <<< [apiv2][body] POST https://accounts.google.com/o/oauth2/token [omitted]
[info] 
[info] ✔  Success! Logged in as ldliangcool@gmail.com 
[debug] [2025-08-20T23:16:57.334Z] <<< [apiv2][status] GET https://firebase-public.firebaseio.com/cli.json 200
[debug] [2025-08-20T23:16:57.334Z] <<< [apiv2][body] GET https://firebase-public.firebaseio.com/cli.json {"cloudBuildErrorAfter":1594252800000,"cloudBuildWarnAfter":1590019200000,"defaultNode10After":1594252800000,"minVersion":"3.0.5","node8DeploysDisabledAfter":1613390400000,"node8RuntimeDisabledAfter":1615809600000,"node8WarnAfter":1600128000000}
[debug] [2025-08-20T23:17:06.321Z] Error: Timed out.
    at Timeout._onTimeout (/Users/andy/.nvm/versions/node/v20.19.0/lib/node_modules/firebase-tools/lib/utils.js:272:49)
    at listOnTimeout (node:internal/timers:581:17)
    at process.processTimers (node:internal/timers:519:7)
[error] 
[error] Error: An unexpected error has occurred.
